2025-07-15 15:26:14,542 - INFO - ====== 开始分别运行所有实验 ======
2025-07-15 15:26:14,543 - INFO - 步骤1: 生成证书数据集
2025-07-15 15:26:14,543 - INFO - 运行命令：['python', 'generate_dataset.py'] (CWD: /Users/yangzongyou/Downloads/iccip 2022/code_exp/scripts)
2025-07-15 15:26:21,620 - INFO - 命令成功完成：['python', 'generate_dataset.py']
2025-07-15 15:26:21,620 - INFO - 步骤2: 检查Hardhat节点
2025-07-15 15:26:21,622 - INFO - Hardhat节点未运行，正在启动...
2025-07-15 15:26:31,630 - INFO - Hardhat节点已成功启动
2025-07-15 15:26:31,631 - INFO - 运行 实验1: 基础性能评估
2025-07-15 15:26:31,631 - INFO - 运行实验1 - 基础性能评估
2025-07-15 15:26:31,632 - INFO - 运行命令：['python', 'temp_exp1.py'] (CWD: /Users/yangzongyou/Downloads/iccip 2022/code_exp/scripts)
2025-07-15 15:26:32,631 - ERROR - 命令执行失败：['python', 'temp_exp1.py']
2025-07-15 15:26:32,631 - ERROR - 错误输出：Traceback (most recent call last):
  File "/Users/yangzongyou/Downloads/iccip 2022/code_exp/scripts/temp_exp1.py", line 13, in <module>
    from scripts.simulation import run_experiment_1_baseline_performance, BlockchainHelper, CERTIFICATE_ARTIFACT_PATH, BASELINE_REVOCATION_ARTIFACT_PATH
ImportError: cannot import name 'run_experiment_1_baseline_performance' from 'scripts.simulation' (/Users/yangzongyou/Downloads/iccip 2022/code_exp/scripts/simulation.py)

2025-07-15 15:26:32,631 - INFO - 已删除临时脚本: /Users/yangzongyou/Downloads/iccip 2022/code_exp/scripts/temp_exp1.py
2025-07-15 15:26:32,631 - ERROR - 实验1: 基础性能评估 运行失败，继续下一个实验
2025-07-15 15:26:32,631 - INFO - 运行 实验2: 吞吐量分析
2025-07-15 15:26:32,631 - INFO - 运行实验2 - 系统吞吐量测试
2025-07-15 15:26:32,631 - INFO - 运行命令：['python', 'temp_exp2.py'] (CWD: /Users/yangzongyou/Downloads/iccip 2022/code_exp/scripts)
2025-07-15 15:33:54,845 - INFO - 命令成功完成：['python', 'temp_exp2.py']
2025-07-15 15:33:54,846 - INFO - 已删除临时脚本: /Users/yangzongyou/Downloads/iccip 2022/code_exp/scripts/temp_exp2.py
2025-07-15 15:33:54,846 - INFO - 实验2: 吞吐量分析 运行成功
2025-07-15 15:33:54,846 - INFO - 运行 实验3: 可扩展性分析
2025-07-15 15:33:54,846 - INFO - 运行实验3 - 可扩展性测试
2025-07-15 15:33:54,847 - INFO - 运行命令：['python', 'temp_exp3.py'] (CWD: /Users/yangzongyou/Downloads/iccip 2022/code_exp/scripts)
2025-07-15 15:34:52,386 - INFO - 命令成功完成：['python', 'temp_exp3.py']
2025-07-15 15:34:52,387 - INFO - 已删除临时脚本: /Users/yangzongyou/Downloads/iccip 2022/code_exp/scripts/temp_exp3.py
2025-07-15 15:34:52,387 - INFO - 实验3: 可扩展性分析 运行成功
2025-07-15 15:34:52,387 - INFO - 运行 实验4: 存储成本对比分析
2025-07-15 15:34:52,387 - INFO - 运行实验4 - 存储成本分析
2025-07-15 15:34:52,388 - INFO - 运行命令：['python', 'temp_exp4.py'] (CWD: /Users/yangzongyou/Downloads/iccip 2022/code_exp/scripts)
2025-07-15 15:34:53,422 - ERROR - 命令执行失败：['python', 'temp_exp4.py']
2025-07-15 15:34:53,422 - ERROR - 错误输出：Traceback (most recent call last):
  File "/Users/yangzongyou/Downloads/iccip 2022/code_exp/scripts/temp_exp4.py", line 13, in <module>
    from scripts.simulation import run_experiment_4_storage_cost, BlockchainHelper, CERTIFICATE_ARTIFACT_PATH, BASELINE_REVOCATION_ARTIFACT_PATH
ImportError: cannot import name 'run_experiment_4_storage_cost' from 'scripts.simulation' (/Users/yangzongyou/Downloads/iccip 2022/code_exp/scripts/simulation.py)

2025-07-15 15:34:53,422 - INFO - 已删除临时脚本: /Users/yangzongyou/Downloads/iccip 2022/code_exp/scripts/temp_exp4.py
2025-07-15 15:34:53,422 - ERROR - 实验4: 存储成本对比分析 运行失败，继续下一个实验
2025-07-15 15:34:53,422 - INFO - 运行 实验5: 撤销机制效率分析
2025-07-15 15:34:53,423 - INFO - 运行实验5 - 撤销机制效率分析
2025-07-15 15:34:53,423 - INFO - 运行命令：['python', 'temp_exp5.py'] (CWD: /Users/yangzongyou/Downloads/iccip 2022/code_exp/scripts)
2025-07-15 15:36:33,710 - INFO - 命令成功完成：['python', 'temp_exp5.py']
2025-07-15 15:36:33,712 - INFO - 已删除临时脚本: /Users/yangzongyou/Downloads/iccip 2022/code_exp/scripts/temp_exp5.py
2025-07-15 15:36:33,712 - INFO - 实验5: 撤销机制效率分析 运行成功
2025-07-15 15:36:33,821 - INFO - 已关闭通用Hardhat节点，准备运行实验6
2025-07-15 15:36:38,826 - INFO - 运行 实验6: 节点故障恢复测试
2025-07-15 15:36:38,827 - INFO - 运行实验6 - 节点故障恢复测试
2025-07-15 15:36:38,827 - INFO - 运行命令：['python', '/Users/yangzongyou/Downloads/iccip 2022/code_exp/scripts/run_fault_test.py'] (CWD: /Users/yangzongyou/Downloads/iccip 2022/code_exp)
2025-07-15 15:43:29,880 - INFO - 命令成功完成：['python', '/Users/yangzongyou/Downloads/iccip 2022/code_exp/scripts/run_fault_test.py']
2025-07-15 15:43:29,880 - INFO - 实验6: 节点故障恢复测试 运行成功
2025-07-15 15:43:29,880 - INFO - 分析所有实验结果
2025-07-15 15:43:29,880 - INFO - 分析所有实验结果
2025-07-15 15:43:29,880 - INFO - 运行命令：['python', 'analyze_results.py'] (CWD: /Users/yangzongyou/Downloads/iccip 2022/code_exp/scripts)
2025-07-15 15:43:32,162 - ERROR - 命令执行失败：['python', 'analyze_results.py']
2025-07-15 15:43:32,162 - ERROR - 错误输出：/Users/yangzongyou/Downloads/iccip 2022/code_exp/scripts/analyze_results.py:55: FutureWarning: 

Passing `palette` without assigning `hue` is deprecated and will be removed in v0.14.0. Assign the `x` variable to `hue` and set `legend=False` for the same effect.

  sns.barplot(x='operation', y='gas_cost', data=df_gas, ax=ax, palette='viridis')
Traceback (most recent call last):
  File "/Users/yangzongyou/Downloads/iccip 2022/code_exp/scripts/analyze_results.py", line 299, in <module>
    main()
  File "/Users/yangzongyou/Downloads/iccip 2022/code_exp/scripts/analyze_results.py", line 290, in main
    analyze_exp2_throughput(summary_file)
  File "/Users/yangzongyou/Downloads/iccip 2022/code_exp/scripts/analyze_results.py", line 75, in analyze_exp2_throughput
    sns.lineplot(x='concurrency_level', y='tps', data=df, marker='o', ax=ax)
  File "/opt/anaconda3/envs/cmbi/lib/python3.11/site-packages/seaborn/relational.py", line 485, in lineplot
    p = _LinePlotter(
        ^^^^^^^^^^^^^
  File "/opt/anaconda3/envs/cmbi/lib/python3.11/site-packages/seaborn/relational.py", line 216, in __init__
    super().__init__(data=data, variables=variables)
  File "/opt/anaconda3/envs/cmbi/lib/python3.11/site-packages/seaborn/_base.py", line 634, in __init__
    self.assign_variables(data, variables)
  File "/opt/anaconda3/envs/cmbi/lib/python3.11/site-packages/seaborn/_base.py", line 679, in assign_variables
    plot_data = PlotData(data, variables)
                ^^^^^^^^^^^^^^^^^^^^^^^^^
  File "/opt/anaconda3/envs/cmbi/lib/python3.11/site-packages/seaborn/_core/data.py", line 58, in __init__
    frame, names, ids = self._assign_variables(data, variables)
                        ^^^^^^^^^^^^^^^^^^^^^^^^^^^^^^^^^^^^^^^
  File "/opt/anaconda3/envs/cmbi/lib/python3.11/site-packages/seaborn/_core/data.py", line 232, in _assign_variables
    raise ValueError(err)
ValueError: Could not interpret value `concurrency_level` for `x`. An entry with this name does not appear in `data`.

2025-07-15 15:43:32,162 - INFO - 运行命令：['python', 'analyze_fault_tolerance.py'] (CWD: /Users/yangzongyou/Downloads/iccip 2022/code_exp/scripts)
2025-07-15 15:43:33,260 - INFO - 命令成功完成：['python', 'analyze_fault_tolerance.py']
2025-07-15 15:43:33,260 - ERROR - 实验结果分析失败
2025-07-15 15:43:33,260 - INFO - ====== 所有实验运行完成 ======
2025-07-15 15:43:33,260 - INFO - 请查看 data/ 目录和 analysis/ 目录获取实验结果和分析
